<?xml version="1.0" ?>
<sdf version='1.6'>
  <model name='iris_fisheye_lens_camera'>
    <link name='base_link'>
      <pose>0 0 0 0 0 0</pose>
      <inertial>
        <pose>0 0 0 0 0 0</pose>
        <mass>1.5</mass>
        <inertia>
          <ixx>0.029125</ixx><ixy>0</ixy><ixz>0</ixz>
          <iyy>0.029125</iyy><iyz>0</iyz><izz>0.055225</izz>
        </inertia>
      </inertial>
      <collision name='base_link_inertia_collision'>
        <pose>0 0 0 0 0 0</pose>
        <geometry><box><size>0.47 0.47 0.11</size></box></geometry>
        <surface>
          <contact><ode><min_depth>0.001</min_depth><max_vel>0</max_vel></ode></contact>
          <friction><ode/></friction>
        </surface>
      </collision>
      <visual name='base_link_inertia_visual'>
        <pose>0 0 0 0 0 0</pose>
        <geometry>
          <mesh><scale>1 1 1</scale><uri>model://iris/meshes/iris.stl</uri></mesh>
        </geometry>
        <material>
          <script><name>Gazebo/DarkGrey</name><uri>file://media/materials/scripts/gazebo.material</uri></script>
        </material>
      </visual>
      <gravity>1</gravity>
      <velocity_decay/>
    </link>

    <link name='/imu_link'>
      <pose>0 0 0.02 0 0 0</pose>
      <inertial>
        <pose>0 0 0 0 0 0</pose>
        <mass>0.015</mass>
        <inertia><ixx>1e-05</ixx><ixy>0</ixy><ixz>0</ixz><iyy>1e-05</iyy><iyz>0</iyz><izz>1e-05</izz></inertia>
      </inertial>
    </link>
    <joint name='/imu_joint' type='revolute'>
      <child>/imu_link</child><parent>base_link</parent>
      <axis><xyz>1 0 0</xyz><limit><lower>0</lower><upper>0</upper><effort>0</effort><velocity>0</velocity></limit></axis>
    </joint>

    {% for i in range(4) %}
    <link name='rotor_{{ i }}'>
      <pose>{{ [0.13, -0.13, 0.13, -0.13][i] }} {{ [-0.22, 0.2, 0.22, -0.2][i] }} 0.023 0 0 0</pose>
      <inertial>
        <mass>0.005</mass>
        <inertia><ixx>9.75e-07</ixx><ixy>0</ixy><ixz>0</ixz><iyy>0.000273104</iyy><iyz>0</iyz><izz>0.000274004</izz></inertia>
      </inertial>
      <collision name='rotor_{{ i }}_collision'>
        <geometry><cylinder><length>0.005</length><radius>0.128</radius></cylinder></geometry>
      </collision>
      <visual name='rotor_{{ i }}_visual'>
        <geometry>
          <mesh><scale>1 1 1</scale><uri>model://iris/meshes/iris_prop_{{ 'ccw' if i < 2 else 'cw' }}.dae</uri></mesh>
        </geometry>
        <material><script><name>Gazebo/{{ 'Blue' if i % 2 == 0 else 'DarkGrey' }}</name></script></material>
      </visual>
    </link>
    <joint name='rotor_{{ i }}_joint' type='revolute'>
      <child>rotor_{{ i }}</child><parent>base_link</parent>
      <axis><xyz>0 0 1</xyz><limit><lower>-1e+16</lower><upper>1e+16</upper></limit></axis>
    </joint>
    <plugin name='motor_model_{{ i }}' filename='libgazebo_motor_model.so'>
      <robotNamespace/><jointName>rotor_{{ i }}_joint</jointName><linkName>rotor_{{ i }}</linkName>
      <turningDirection>{{ 'ccw' if i < 2 else 'cw' }}</turningDirection>
      <motorNumber>{{ i }}</motorNumber>
      <motorSpeedPubTopic>/motor_speed/{{ i }}</motorSpeedPubTopic>
      <commandSubTopic>/gazebo/command/motor_speed</commandSubTopic>
      <motorConstant>5.84e-06</motorConstant><momentConstant>0.06</momentConstant>
      <rotorDragCoefficient>0.000175</rotorDragCoefficient><rollingMomentCoefficient>1e-06</rollingMomentCoefficient>
      <rotorVelocitySlowdownSim>10</rotorVelocitySlowdownSim>
    </plugin>
    {% endfor %}

    <include>
      <uri>model://gps</uri><pose>0.05 0 0.04 0 0 0</pose><name>gps0</name>
    </include>
    <joint name='gps0_joint' type='fixed'><child>gps0::link</child><parent>base_link</parent></joint>

    <plugin name='groundtruth_plugin' filename='libgazebo_groundtruth_plugin.so'><robotNamespace/></plugin>
    <plugin name='magnetometer_plugin' filename='libgazebo_magnetometer_plugin.so'>
      <robotNamespace/><pubRate>100</pubRate><noiseDensity>0.0004</noiseDensity>
      <magTopic>/mag</magTopic>
    </plugin>
    <plugin name='barometer_plugin' filename='libgazebo_barometer_plugin.so'>
      <robotNamespace/><pubRate>50</pubRate><baroTopic>/baro</baroTopic>
    </plugin>

    <plugin name='mavlink_interface' filename='libgazebo_mavlink_interface.so'>
      <robotNamespace/>
      <imuSubTopic>/imu</imuSubTopic><magSubTopic>/mag</magSubTopic><baroSubTopic>/baro</baroSubTopic>
      <mavlink_addr>INADDR_ANY</mavlink_addr>
      <mavlink_tcp_port>{{ mavlink_tcp_port }}</mavlink_tcp_port>
      <mavlink_udp_port>{{ mavlink_udp_port }}</mavlink_udp_port>
      <serialEnabled>0</serialEnabled><serialDevice>/dev/ttyACM0</serialDevice>
      <baudRate>921600</baudRate><qgc_addr>INADDR_ANY</qgc_addr><qgc_udp_port>14550</qgc_udp_port>
      <sdk_addr>INADDR_ANY</sdk_addr><sdk_udp_port>14540</sdk_udp_port>
      <hil_mode>0</hil_mode><hil_state_level>0</hil_state_level>
      <send_vision_estimation>0</send_vision_estimation><send_odometry>1</send_odometry><enable_lockstep>1</enable_lockstep><use_tcp>1</use_tcp>
      <motorSpeedCommandPubTopic>/gazebo/command/motor_speed</motorSpeedCommandPubTopic>
      <control_channels>
        {% for i in range(4) %}
        <channel name='rotor{{ i+1 }}'>
          <input_index>{{ i }}</input_index><input_offset>0</input_offset><input_scaling>1000</input_scaling>
          <zero_position_disarmed>0</zero_position_disarmed><zero_position_armed>100</zero_position_armed><joint_control_type>velocity</joint_control_type>
        </channel>
        {% endfor %}
      </control_channels>
    </plugin>

    <link name="fisheye_camera_link">
      <pose>0.1 0 0 0 0 0</pose>
      <inertial>
        <mass>0.015</mass>
        <inertia><ixx>4.15e-6</ixx><iyy>2.407e-6</iyy><izz>2.407e-6</izz></inertia>
      </inertial>
      <visual name="visual">
        <geometry><box><size>0.02 0.05 0.05</size></box></geometry>
      </visual>
      <sensor name="camera" type="wideanglecamera">
        <camera>
          <horizontal_fov>3.1415</horizontal_fov>
          <image><width>640</width><height>480</height><format>R8G8B8</format></image>
          <clip><near>0.1</near><far>100</far></clip>
          <lens>
            <type>equidistant</type><scale_to_hfov>true</scale_to_hfov><cutoff_angle>1.5707</cutoff_angle>
          </lens>
        </camera>
        <always_on>1</always_on><update_rate>3</update_rate>
        <plugin name="camera_controller" filename="libgazebo_ros_camera.so">
          <ros>
            <namespace>/drone{{ mavlink_id }}</namespace>
            <remapping>image_raw:=camera/image_raw</remapping>
          </ros>
          <camera_name>camera</camera_name><frame_name>camera_link</frame_name>
        </plugin>
      </sensor>
    </link>
    <joint name="fisheye_camera_joint" type="fixed">
      <child>fisheye_camera_link</child><parent>base_link</parent>
    </joint>

    <static>0</static>
    <plugin name='rotors_gazebo_imu_plugin' filename='libgazebo_imu_plugin.so'>
      <robotNamespace/><linkName>/imu_link</linkName><imuTopic>/imu</imuTopic>
    </plugin>
  </model>
</sdf>